Workbook

Sheet GRC
B1: 7:00 - 7:30 | C1: 7:30 - 8:00 | D1: 8:00 - 8:30 | E1: 8:30 - 9:00 | F1: 9:00 - 9:30 | G1: 9:30 - 10:00 | H1: 10:00 - 10:30 | I1: 10:30 - 11:00 | J1: 11:00 - 11:30 | K1: 11:30 - 12:00 | L1: 12:00 - 12:30 | M1: 12:30 - 1:00 | N1: 1:00 - 1:30 | O1: 1:30 - 2:00 | P1: 2:00 - 2:30 | Q1: 2:30 - 3:00 | R1: 3:00 - 3:30 | S1: 3:30 - 4:00 | T1: 4:00 - 4:30 | U1: 4:30 - 5:00 | V1: 5:00 - 5:30 | W1: 5:30 - 6:00 | X1: 6:00 - 6:30 | Y1: 6:30 - 7:00
A2: Monday | B2: Jacob B | C2: Jacob B | D2: Jacob B | H2: Andrew | I2: Andrew | J2: Andrew | K2: Andrew | L2: Andrew | M2: Andrew | N2: Andrew | O2: Andrew | P2: Andrew | Q2: Andrew | R2: Andrew
B3: Jamie | C3: Jamie | D3: Jamie | E3: Jamie (8:45) | F3: ORTSOC Project (428) | H3: Ethan H | I3: Ethan H | J3: Ethan H | K3: Ethan H | L3: Ethan H | M3: Ethan H | P3: Alejandro | Q3: Alejandro | R3: Alejandro | S3: Alejandro | T3: Alejandro | U3: Alejandro | V3: Alejandro | W3: Alejandro
J4: Luc | K4: Luc | L4: Luc | M4: Luc | N4: Luc | O4: Luc | P4: Luc | Q4: Luc | R4: Shengwei | S4: Shengwei | T4: Shengwei | U4: Shengwei
B5: Matthew M | C5: Matthew M | D5: Matthew M | H5: Ethan D | I5: Ethan D | J5: Ethan D | K5: Ethan D | L5: Dongyoung | M5: Dongyoung | N5: Dongyoung | O5: Dongyoung | P5: Dongyoung | Q5: Dongyoung | R5: Minca | S5: Minca | T5: Minca | U5: Minca | V5: Minca | W5: Minca | X5: Minca | Y5: Minca
H6: Max R | I6: Max R | J6: Max R | K6: Max R | L6: Tycho | M6: Tycho | N6: Tycho | O6: Tycho | P6: Tycho | Q6: Tycho | R6: Tycho | S6: Tycho | T6: Tycho | U6: Tycho | V6: Tycho | W6: Tycho | X6: Tycho | Y6: Tycho
H7: Jackie | I7: Jackie | J7: Jackie | K7: Jackie | L7: Jackie | M7: Jackie | N7: Jackie | O7: Jackie | P7: Joshua | Q7: Joshua | R7: Joshua | S7: Joshua | T7: Joshua | U7: Joshua
B8: Devin | C8: Devin | D8: Devin | I8: Devin | J8: Devin | K8: Devin | L8: Zyan | M8: Zyan | N8: Zyan | O8: Zyan | P8: Zyan | Q8: Zyan | R8: Zyan | S8: Zyan | T8: Tetiana | U8: Tetiana | V8: Tetiana | W8: Tetiana | X8: Tetiana | Y8: Tetiana
H9: Seojin | I9: Seojin | J9: Seojin | K9: Seojin | L9: Seojin | M9: Seojin | P9: Christopher | Q9: Christopher | R9: Christopher | S9: Christopher | T9: Christopher | U9: Christopher
J10: Jaden | K10: Jaden | L10: Jaden | M10: Jaden | N10: Jaden | O10: Jaden | U10: Edith | V10: Edith | W10: Edith | X10: Edith | Y10: Edith
H11: Nina | I11: Nina | J11: Nina | K11: Nina | L11: Nina | M11: Nina | N11: Nina | O11: Nina | P11: Gabriel M | Q11: Gabriel M | R11: Gabriel M | S11: Gabriel M | T11: Gabriel M | U11: Gabriel M
H12: Henry | I12: Henry | J12: Henry | K12: Henry | L12: Henry | M12: Henry | N12: Henry | O12: Henry | Q12: Lorelei | R12: Lorelei | S12: Lorelei | T12: Lorelei | U12: Lorelei | V12: Lorelei
H13: Seth | I13: Seth | J13: Seth | K13: Seth | L13: Seth | M13: Seth | N13: Seth | O13: Seth | P13: Seth | S13: Richie | T13: Richie | U13: Richie | V13: Richie | W13: Richie | X13: Richie
H14: Liam | I14: Liam | J14: Liam | K14: Liam | L14: Liam | M14: Liam | N14: Liam | O14: Liam | P14: Liam | Q14: Liam | R14: Liam | T14: Brian | U14: Brian | V14: Brian | W14: Brian
H15: Atticus | I15: Atticus | J15: Atticus | K15: Atticus | M15: Peter | N15: Peter | O15: Peter | P15: Peter | R15: Zhengye | S15: Zhengye | T15: Zhengye | U15: Zhengye | V15: Zhengye | W15: Zhengye
H16: Mayra | I16: Mayra | J16: Mayra | K16: Mayra | L16: Mayra | M16: Mayra | N16: Mayra | O16: Mayra
H17: Finlay | I17: Finlay | J17: Finlay | K17: Finlay | L17: Finlay | M17: Finlay | N17: Finlay | O17: Finlay | P17: Finlay | Q17: Finlay | R17: Finlay
H18: Vi | I18: Vi | J18: Vi | K18: Vi | L18: Vi | U18: Vi | V18: Vi | W18: Vi | X18: Vi | Y18: Vi
H19: Max C | I19: Max C | J19: Max C | K19: Max C | L19: Max C | M19: Max C | N19: Max C | O19: Max C
H20: Gavi | I20: Gavi | J20: Gavi | K20: Gavi | L20: Gavi | M20: Gavi | N20: Gavi | O20: Gavi
E21: Nikhil | F21: Nikhil | G21: Nikhil | H21: Nikhil | I21: Nikhil | J21: Nikhil
B23: =COUNTA(B2:B22) -> 4 | C23: =COUNTA(C2:C22) -> 4 | D23: =COUNTA(D2:D22) -> 4 | E23: =COUNTA(E2:E22) -> 2 | F23: =COUNTA(F2:F22) -> 2 | G23: =COUNTA(G2:G22) -> 1 | H23: =COUNTA(H2:H22) -> 17 | I23: =COUNTA(I2:I22) -> 18 | ... K23: =COUNTA(K2:K22) -> 19 | L23: =COUNTA(L2:L21) -> 18 | M23: =COUNTA(M2:M21) -> 18 | N23: =COUNTA(N2:N22) -> 16 | O23: =COUNTA(O2:O22) -> 16 | P23: =COUNTA(P2:P22) -> 13 | Q23: =COUNTA(Q2:Q22) -> 12 | R23: =COUNTA(R2:R22) -> 13 | S23: =COUNTA(S2:S22) -> 11 | T23: =COUNTA(T2:T22) -> 12 | U23: =COUNTA(U2:U22) -> 14 | ... Y23: =COUNTA(Y2:Y22) -> 5
A24: Tuesday | B24: Jacob B | C24: Jacob B | D24: Jacob B | E24: Jacob B | F24: Jacob B | G24: Jacob B | H24: Zhengye | I24: Zhengye | J24: Zhengye | K24: Zhengye | L24: Zhengye | M24: Zhengye | N24: Zhengye | O24: Zhengye | P24: Shengwei | Q24: Shengwei | R24: Shengwei | S24: Shengwei | T24: Shengwei | U24: Shengwei | V24: Tycho | W24: Tycho | X24: Tycho | Y24: Tycho
Q25: Dongyoung | R25: Dongyoung | S25: Dongyoung | T25: Dongyoung | U25: Dongyoung | V25: Leo | W25: Leo | X25: Leo | Y25: Leo
B26: Jamie | C26: Jamie | D26: Jamie | E26: Jamie | F26: Jamie | G26: Jamie | H26: Ethan H | I26: Ethan H | J26: Ethan H | K26: Ethan H | L26: Ethan H | M26: Ethan H | P26: Jackie | Q26: Jackie | R26: Jackie | S26: Jackie | T26: Jackie | U26: Jackie
K27: Gabriel M | L27: Gabriel M | M27: Gabriel M | N27: Gabriel M | P27: Zyan | Q27: Zyan | R27: Zyan | S27: Zyan | T27: Zyan | U27: Zyan
F28: Troy B | G28: Troy B | H28: Troy B | I28: Troy B | J28: Troy B | O28: Troy B | P28: Troy B | Q28: Troy B | R28: Troy B | S28: Troy B | T28: Troy B
F29: Ethan D | G29: Ethan D | H29: Ethan D | I29: Ethan D | J29: Ethan D | K29: Ethan D | L29: Ethan D | M29: Ethan D | N29: Joshua | O29: Joshua | P29: Joshua | Q29: Joshua | R29: Joshua | S29: Joshua | T29: Joshua | U29: Joshua
C30: Arianna | D30: Arianna | E30: Arianna | F30: Arianna | H30: Jaden | I30: Jaden | J30: Jaden | K30: Jaden | L30: Jaden | N30: Christopher | O30: Christopher | P30: Christopher | Q30: Christopher | R30: Christopher | S30: Christopher | T30: Christopher | U30: Christopher
B31: Matthew M | C31: Matthew M | D31: Matthew M | E31: Matthew M | F31: Matthew M | G31: Matthew M | H31: Matthew M | L31: Seojin | M31: Seojin | N31: Seojin | O31: Seojin | P31: Seojin | Q31: Seojin | R31: Seojin
F32: Sjoerd | G32: Sjoerd | H32: Sjoerd | I32: Sjoerd | J32: Sjoerd | K32: Sjoerd | L32: Sjoerd | M32: Sjoerd | Q32: Jayson | R32: Jayson | S32: Jayson | T32: Jayson | U32: Jayson | V32: Jayson
B33: Devin | C33: Devin | D33: Devin | E33: Devin | F33: Devin | N33: Atticus | O33: Atticus | P33: Atticus | Q33: Atticus | R33: Atticus
E34: Nikhil | F34: Nikhil | G34: Nikhil | H34: Nikhil | I34: Nikhil | J34: Nikhil | N34: Max R | O34: Max R | P34: Max R | Q34: Max R | R34: Max R | S34: Max R | T34: Max R
J35: Peter | K35: Peter | L35: Peter | M35: Peter | N35: Peter | Q35: Edith | R35: Edith | S35: Edith | T35: Edith | U35: Edith | V35: Edith | W35: Edith | X35: Edith | Y35: Edith
D36: Silas | E36: Silas | F36: Silas | G36: Silas | H36: Silas | I36: Silas | J36: Silas | M36: Lorelei | N36: Lorelei | O36: Lorelei | P36: Lorelei | Q36: Lorelei | R36: Richie | S36: Richie | T36: Richie | U36: Richie | V36: Richie | W36: Richie
Q37: Brian | R37: Brian | S37: Brian | T37: Brian | U37: Brian
B47: =COUNTA((B24:B46)) -> 4 | C47: =COUNTA((C24:C46)) -> 5 | D47: =COUNTA((D24:D46)) -> 6 | E47: =COUNTA((E24:E46)) -> 7 | F47: =COUNTA((F24:F46)) -> 10 | G47: =COUNTA((G24:G46)) -> 8 | H47: =COUNTA((H24:H46)) -> 9 | I47: =COUNTA((I24:I45)) -> 8 | J47: =COUNTA((J24:J45)) -> 9 | K47: =COUNTA((K24:K45)) -> 7 | L47: =COUNTA((L24:L45)) -> 8 | M47: =COUNTA((M24:M46)) -> 8 | N47: =COUNTA((N24:N46)) -> 9 | O47: =COUNTA((O24:O46)) -> 8 | P47: =COUNTA((P24:P46)) -> 10 | Q47: =COUNTA((Q24:Q46)) -> 14 | R47: =COUNTA((R24:R46)) -> 14 | S47: =COUNTA((S24:S46)) -> 12 | T47: =COUNTA((T24:T46)) -> 12 | ... Y47: =COUNTA((Y24:Y46)) -> 3
A48: Wednesday | B48: Jacob B | C48: Jacob B | D48: Jacob B | H48: Andrew | I48: Andrew | J48: Andrew | K48: Andrew | L48: Andrew | M48: Andrew | N48: Andrew | O48: Andrew | P48: Andrew | Q48: Andrew | R48: Andrew
B49: Jamie | C49: Jamie | D49: Jamie | E49: Jamie (8:45) | F49: ORTSOC Project (428) | J49: Luc | K49: Luc | L49: Luc | M49: Luc | N49: Luc | O49: Luc | P49: Shengwei | Q49: Shengwei | R49: Shengwei | S49: Shengwei | T49: Shengwei | U49: Shengwei
H50: Jake | I50: Jake | J50: Jake | K50: Jake | L50: Jake | M50: Jake | T50: Brian | U50: Brian | V50: Brian | W50: Brian
...

Sheet SecOps
B1: 7:00 - 7:30 | C1: 7:30 - 8:00 | D1: 8:00 - 8:30 | E1: 8:30 - 9:00 | F1: 9:00 - 9:30 | G1: 9:30 - 10:00 | H1: 10:00 - 10:30 | I1: 10:30 - 11:00 | J1: 11:00 - 11:30 | K1: 11:30 - 12:00 | L1: 12:00 - 12:30 | M1: 12:30 - 1:00 | N1: 1:00 - 1:30 | O1: 1:30 - 2:00 | P1: 2:00 - 2:30 | Q1: 2:30 - 3:00 | R1: 3:00 - 3:30 | S1: 3:30 - 4:00 | T1: 4:00 - 4:30 | U1: 4:30 - 5:00 | V1: 5:00 - 5:30 | W1: 5:30 - 6:00 | X1: 6:00 - 6:30 | Y1: 6:30 - 7:00
A2: Monday | B2: Gabriel N | C2: Gabriel N | D2: Gabriel N | H2: Luke | I2: Luke | J2: Luke | K2: Luke | L2: Luke | M2: Luke | N2: Luke | O2: Luke | Q2: Jinhui | R2: Jinhui | S2: Jinhui | T2: Jinhui | U2: Jinhui | V2: Jinhui
B3: Reif | C3: Reif | D3: Reif | F3: ORTSOC Project (428) | H3: Reif | I3: Reif | J3: Reif | K3: Reif | L3: Reif | M3: Reif | N3: Reif | O3: Reif | P3: Troy L | Q3: Troy L | R3: Troy L | S3: Troy L | T3: Troy L | U3: Troy L
N4: Mason | O4: Mason | P4: Mason | Q4: Mason | R4: Mason | S4: Mason | V4: Ryan | W4: Ryan | X4: Ryan | Y4: Ryan
H5: Kyla | I5: Kyla | J5: Kyla | K5: Kyla | L5: Kyla | M5: Kyla | N5: Kyla (1:15) | P5: Palmer | Q5: Palmer | R5: Palmer | S5: Palmer | T5: Alexander | U5: Alexander | V5: Alexander | W5: Alexander
B6: Ryan | C6: Ryan | D6: Ryan | J6: Garrett | K6: Garrett | L6: Garrett | M6: Garrett | N6: Garrett | P6: Chu-Xuan | Q6: Chu-Xuan | R6: Chu-Xuan | S6: Chu-Xuan | T6: Chu-Xuan | U6: Chu-Xuan
B7: Luca | C7: Luca | D7: Luca | J7: Matthew C | K7: Matthew C | L7: Matthew C | M7: Matthew C | P7: Aiden M | Q7: Aiden M | R7: Aiden M | S7: Aiden M | T7: Aiden M | U7: Aiden M | V7: Aiden M | W7: Aiden M
B8: Gabriel V | C8: Gabriel V | D8: Gabriel V | E8: Gabriel V | J8: Bon | K8: Bon | L8: Bon | M8: Bon | N8: Bon | O8: Bon | P8: Bon | Q8: Bon | R8: Benjamin L | S8: Benjamin L | T8: Benjamin L | U8: Benjamin L | V8: Benjamin L
J9: Nico | K9: Nico | L9: Nico | M9: Nico | N9: Nico | O9: Nico | P9: Nico | Q9: Nico
K10: Angela | L10: Angela | M10: Angela | N10: Angela | O10: Angela | P10: Angela | Q10: Angela | R10: Angela | S10: Angela | T10: Angela
I11: Carter | J11: Carter | K11: Carter | L11: Carter | M11: Carter | N11: Carter | O11: Carter | P11: Carter | Q11: Samuel | R11: Samuel | S11: Samuel | T11: Samuel
H12: Alexa | I12: Alexa | J12: Alexa | K12: Alexa | L12: Alexa | M12: Alexa | N12: Alexa | O12: Alexa
H13: Christian | I13: Christian | J13: Christian | K13: Christian | L13: Christian | M13: Christian
L14: Melina | M14: Melina | N14: Melina | O14: Melina
H15: Aiden R | I15: Aiden R | J15: Aiden R | K15: Aiden R | L15: Aiden R | M15: Aiden R | N15: Aiden R | O15: Aiden R
H16: Jordan | I16: Jordan | J16: Jordan | K16: Jordan | L16: Jordan | M16: Jordan | N16: Jordan | O16: Jordan
H17: Jacob P | I17: Jacob P | J17: Jacob P | K17: Jacob P | L17: Jacob P | M17: Jacob P | N17: Jacob P | O17: Jacob P
H18: Ross | I18: Ross | J18: Ross | K18: Ross | L18: Ross | M18: Ross | N18: Ross | O18: Ross | P18: Ross | Q18: Ross | R18: Ross
H19: Reynaud | I19: Reynaud | J19: Reynaud | K19: Reynaud | L19: Reynaud
L20: Theodore | M20: Theodore | N20: Theodore | O20: Theodore
E21: Luke B | F21: Luke B | G21: Luke B | H21: Luke B | I21: Luke B | J21: Luke B | K21: Luke B
H22: Jawad | I22: Jawad | J22: Jawad | K22: Jawad | L22: Jawad | M22: Jawad
B23: =COUNTA(B2:B22) -> 5 | C23: =COUNTA(C2:C22) -> 5 | D23: =COUNTA(D2:D22) -> 5 | E23: =COUNTA(E2:E22) -> 2 | F23: =COUNTA(F2:F22) -> 2 | G23: =COUNTA(G2:G22) -> 1 | H23: =COUNTA(H2:H22) -> 12 | I23: =COUNTA(I2:I22) -> 13 | ... K23: =COUNTA(K2:K22) -> 18 | L23: =COUNTA(L2:L21) -> 18 | M23: =COUNTA(M2:M21) -> 17 | N23: =COUNTA(N2:N22) -> 16 | O23: =COUNTA(O2:O22) -> 14 | P23: =COUNTA(P2:P22) -> 10 | Q23: =COUNTA(Q2:Q22) -> 11 | R23: =COUNTA(R2:R22) -> 10 | S23: =COUNTA(S2:S22) -> 9 | T23: =COUNTA(T2:T22) -> 8 | U23: =COUNTA(U2:U22) -> 6 | ... Y23: =COUNTA(Y2:Y22) -> 1
A24: Tuesday | B24: Gabriel N | C24: Gabriel N | D24: Gabriel N | E24: Gabriel N | F24: Gabriel N | G24: Gabriel N | H24: Gabriel N | I24: Gabriel N | J24: Max T | K24: Max T | L24: Max T | M24: Max T | N24: Max T | O24: Max T | P24: Max T | Q24: Max T | R24: Benjamin B | S24: Benjamin B | T24: Benjamin B | U24: Benjamin B | V24: Benjamin B | W24: Benjamin B | X24: Benjamin B | Y24: Benjamin B
B25: Alexa | C25: Alexa | D25: Alexa | L25: Garrett | M25: Garrett | N25: Garrett | O25: Garrett | P25: Garrett | Q25: Garrett | T25: Mia | U25: Mia | V25: Mia | W25: Mia
B26: Aden | C26: Aden | D26: Aden | E26: Aden | F26: Aden | H26: Luke | I26: Luke | J26: Luke | K26: Benjamin L | L26: Benjamin L | M26: Benjamin L | N26: Benjamin L | O26: Benjamin L | P26: Benjamin L | Q26: Jinhui | R26: Jinhui | S26: Jinhui | T26: Jinhui | U26: Jinhui | V26: Jinhui
B27: Malik | C27: Malik | D27: Malik | E27: Malik | F27: Malik | G27: Malik | H27: Malik | I27: Malik | J27: Malik | K27: Malik | L27: Malik | Q27: Bon | R27: Bon | S27: Bon | V27: Reynaud | W27: Reynaud | X27: Reynaud | Y27: Reynaud
B28: Ryan | C28: Ryan | D28: Ryan | E28: Ryan | F28: Mason | G28: Mason | H28: Mason | I28: Mason | J28: Mason | K28: Mason | P28: Aiden M | Q28: Aiden M | R28: Aiden M | S28: Aiden M | T28: Aiden M | U28: Aiden M | V28: Theodore | W28: Theodore | X28: Theodore | Y28: Theodore
F29: Kyla | G29: Kyla | H29: Kyla | S29: Kyla | T29: Kyla | U29: Kyla
F30: Matthew C | G30: Matthew C | H30: Matthew C | I30: Matthew C | J30: Matthew C | K30: Matthew C | L30: Matthew C | M30: Matthew C | N30: Matthew C | O30: Angela | P30: Angela | Q30: Angela | R30: Angela | S30: Angela | T30: Angela
F31: Palmer | G31: Palmer | H31: Palmer | I31: Palmer | J31: Palmer | K31: Palmer | N31: Troy L | O31: Troy L | P31: Troy L | Q31: Troy L | R31: Troy L | S31: Troy L
H32: Alexander | I32: Alexander | J32: Alexander | K32: Alexander | L32: Alexander | M32: Alexander | N32: Alexander | O32: Alexander
H33: Christian | I33: Christian | J33: Christian | K33: Christian | L33: Christian | M33: Christian | N33: Caleb | O33: Caleb | P33: Caleb | Q33: Caleb | R33: Caleb | S33: Caleb | T33: Caleb | U33: Caleb | V33: Caleb | W33: Caleb | X33: Caleb | Y33: Caleb
F34: Gabriel V | G34: Gabriel V | H34: Gabriel V | I34: Gabriel V | J34: Gabriel V | L34: Melina | M34: Melina | N34: Melina | O34: Melina | P34: Chu-Xuan | Q34: Chu-Xuan | R34: Chu-Xuan | S34: Chu-Xuan | T34: Chu-Xuan | U34: Chu-Xuan
F35: Aiden R | G35: Aiden R | H35: Aiden R | I35: Aiden R | J35: Aiden R | K35: Aiden R | N35: Samuel | O35: Samuel | P35: Samuel | Q35: Samuel | R35: Samuel | S35: Samuel | T35: Samuel | U35: Samuel
F36: Logan | G36: Logan | H36: Logan | I36: Logan | J36: Logan | K36: Logan | L36: Logan | M36: Logan | N36: Logan | O36: Logan | P36: Logan
F37: Skye | G37: Skye | H37: Skye | I37: Skye | J37: Skye | K37: Skye | M37: Jawad | N37: Jawad | O37: Jawad | P37: Jawad
E38: Tate | F38: Tate | G38: Tate | H38: Tate | I38: Tate | J38: Tate | K38: Tate | L38: Tate
K39: Tyler | L39: Tyler | M39: Tyler | N39: Tyler | S39: Tyler | T39: Tyler | U39: Tyler
B47: =COUNTA((B24:B46)) -> 5 | C47: =COUNTA((C24:C46)) -> 5 | D47: =COUNTA((D24:D46)) -> 5 | E47: =COUNTA((E24:E46)) -> 5 | F47: =COUNTA((F24:F46)) -> 12 | G47: =COUNTA((G24:G46)) -> 11 | H47: =COUNTA((H24:H46)) -> 14 | I47: =COUNTA((I24:I45)) -> 13 | J47: =COUNTA((J24:J45)) -> 13 | K47: =COUNTA((K24:K45)) -> 13 | L47: =COUNTA((L24:L45)) -> 11 | M47: =COUNTA((M24:M46)) -> 10 | N47: =COUNTA((N24:N46)) -> 12 | O47: =COUNTA((O24:O46)) -> 11 | P47: =COUNTA((P24:P46)) -> 11 | Q47: =COUNTA((Q24:Q46)) -> 10 | R47: =COUNTA((R24:R46)) -> 9 | S47: =COUNTA((S24:S46)) -> 11 | T47: =COUNTA((T24:T46)) -> 10 | ... Y47: =COUNTA((Y24:Y46)) -> 4
...

Sheet Copy of Mentors
B1: 7:00 - 7:30 | C1: 7:30 - 8:00 | D1: 8:00 - 8:30 | E1: 8:30 - 9:00 | F1: 9:00 - 9:30 | G1: 9:30 - 10:00 | H1: 10:00 - 10:30 | I1: 10:30 - 11:00 | J1: 11:00 - 11:30 | K1: 11:30 - 12:00 | L1: 12:00 - 12:30 | M1: 12:30 - 1:00 | N1: 1:00 - 1:30 | O1: 1:30 - 2:00 | P1: 2:00 - 2:30 | Q1: 2:30 - 3:00 | R1: 3:00 - 3:30 | S1: 3:30 - 4:00 | T1: 4:00 - 4:30 | U1: 4:30 - 5:00 | V1: 5:00 - 5:30 | W1: 5:30 - 6:00 | X1: 6:00 - 6:30 | Y1: 6:30 - 7:00
A2: Monday | D2: Brandon | E2: Brandon | F2: Brandon | G2: Brandon | H2: Brandon | I2: Brandon | J2: Rebecca | K2: Rebecca | L2: Rebecca | M2: Rebecca | N2: Rebecca | O2: Rebecca | P2: Rebecca | Q2: Rebecca | R2: Radhika | S2: Radhika | X2: Radhika | Y2: Radhika
A3: Tuesday | D3: Brandon | E3: Brandon | F3: Brandon | G3: Brandon | H3: Brandon | I3: Brandon | J3: Rebecca | K3: Rebecca | L3: Rebecca | M3: Rebecca | N3: Radhika | O3: Radhika | P3: Radhika | Q3: Radhika | R3: Radhika | S3: Radhika | T3: Avani | U3: Avani | V3: Avani | W3: Avani
A4: Wednesday | D4: Brandon | E4: Brandon | F4: Brandon | G4: Brandon | H4: Rebecca | I4: Rebecca | J4: Rebecca | K4: Rebecca | L4: Rebecca | M4: Rebecca | N4: Dave | O4: Dave | P4: Radhika | Q4: Radhika | R4: Radhika | S4: Radhika
A5: Thursday | D5: Brandon | E5: Brandon | F5: Brandon | G5: Brandon | H5: Rebecca | I5: Rebecca | J5: Rebecca | K5: Rebecca | L5: Radhika | M5: Radhika | N5: Radhika | O5: Radhika | P5: Radhika | Q5: Radhika | R5: Radhika | S5: Radhika | T5: Avani | U5: Avani | V5: Avani | W5: Avani
A6: Friday | D6: Brandon | E6: Brandon | F6: Brandon | G6: Brandon | J6: Rebecca | K6: Rebecca | L6: Rebecca | M6: Rebecca | N6: Michelle | O6: Michelle | P6: Avani | Q6: Avani | R6: Avani | S6: Avani | T6: Avani | U6: Avani | V6: Avani | W6: Avani
B9: Avani | C9: =COUNTIF($B$2:$Y$6,B9)/2 + COUNTIF($B$2:$Y$6,$P$6)/2 -> 16 | D9: x
B10: Brandon | C10: =COUNTIF($B$2:$Y$6,B10)/2 -> 12 | D10: x
B11: Radhika | C11: =COUNTIF($B$2:$Y$6,B11)/2 + COUNTIF($B$2:$Y$6,$P$6)/2 -> 19 | J11: Rebecca | K11: =4+2+3+2+2 -> 13 | L11: 13
B12: Rebecca | C12: =COUNTIF($B$2:$Y$6,B12)/2 -> 13 | J12: Radhika | K12: =1+3+2+4+1 -> 11 | L12: 13
B13: Dave | C13: =COUNTIF($B$2:$Y$6,B13)/2 -> 1 | J13: Avani | K13: =2+2+4 -> 8 | L13: 10
B14: Michelle | C14: =COUNTIF($B$2:$Y$6,B14)/2 -> 1

Sheet Sch_Draft
A1: Pref | B1: 7:00 - 7:30 | C1: 7:30 - 8:00 | D1: 8:00 - 8:30 | E1: 8:30 - 9:00 | F1: 9:00 - 9:30 | G1: 9:30 - 10:00 | H1: 10:00 - 10:30 | I1: 10:30 - 11:00 | J1: 11:00 - 11:30 | K1: 11:30 - 12:00 | L1: 12:00 - 12:30 | M1: 12:30 - 1:00 | N1: 1:00 - 1:30 | O1: 1:30 - 2:00 | P1: 2:00 - 2:30 | Q1: 2:30 - 3:00 | R1: 3:00 - 3:30 | S1: 3:30 - 4:00 | T1: 4:00 - 4:30 | U1: 4:30 - 5:00 | V1: 5:00 - 5:30 | W1: 5:30 - 6:00 | X1: 6:00 - 6:30 | Y1: 6:30 - 7:00
A2: Monday | E2: Hayden | F2: Hayden | H2: Mike | I2: Mike | J2: Mike | K2: Mike | L2: Mike | M2: Mike | N2: Mike | O2: Mike | R2: Chance | S2: Chance | T2: Chance | U2: Chance | Z2: =COUNTA(B2:Y2)/2 -> 7
H3: Zach | I3: Zach | J3: Zach | K3: Zach | L3: Charlie | M3: Charlie | N3: Charlie | P3: Zach | Q3: Zach | R3: Zach | S3: Zach | T3: Khai | U3: Khai | V3: Khai | W3: Khai | X3: Khai | Y3: Khai | Z3: =COUNTA(B3:Y3)/2 -> 8.5
D4: Emmet | E4: Emmet | F4: Emmet | G4: Emmet | H4: Emmet | I4: Emmet | N4: Hayden | O4: Hayden | P4: Hayden | Q4: Hayden | Z4: =COUNTA(B4:Y4)/2 -> 5
H5: Aaron | I5: Aaron | J5: Aaron | K5: Aaron | L5: Aaron | M5: Aaron | N5: Aaron | O5: Aaron | Z5: =COUNTA(B5:Y5)/2 -> 4
I6: Jarren | J6: Jarren | K6: Jarren | L6: Jarren | M6: Mario S | N6: Mario S | O6: Mario S | P6: Mario S | Q6: Mario S | R6: Mario S | Z6: =COUNTA(B6:Y6)/2 -> 5
L7: Cameron | M7: Cameron | N7: Cameron | O7: Cameron | P7: Cameron | Q7: Cameron | R7: Cameron | S7: Cameron | Z7: =COUNTA(B7:Y7)/2 -> 4
A8: Tuesday | D8: Allen | E8: Allen | F8: Allen | G8: Allen | H8: Allen | I8: Allen | J8: Allen | K8: Allen | N8: Jonathan Mach | O8: Jonathan Mach | P8: Jonathan Mach | Q8: Jonathan Mach | R8: Jonathan Mach | S8: Jonathan Mach | T8: Jonathan Mach | U8: Jonathan Mach | V8: Jonathan Mach | W8: Jonathan Mach | Z8: =COUNTA(B8:Y8)/2 -> 9
J9: Chance | K9: Chance | L9: Chance | M9: Chance | P9: Hayden | Q9: Hayden | Z9: =COUNTA(B9:Y9)/2 -> 3
H10: Charlie | I10: Charlie | J10: Charlie | K10: Charlie | M10: Jarren | N10: Jarren | O10: Jarren | P10: Jarren | Z10: =COUNTA(B10:Y10)/2 -> 4
H11: Jonathan Mach | I11: Jonathan Mach | J11: Jonathan Mach | K11: Jonathan Mach | N11: Jackson | O11: Jackson | P11: Jackson | Q11: Jackson | Z11: =COUNTA(B11:Y11)/2 -> 4
F12: Kyle | G12: Kyle | H12: Kyle | I12: Kyle | J12: Kyle | K12: Kyle | L12: Kyle | M12: Kyle | N12: Ian | O12: Ian | P12: Ian | Q12: Ian | R12: Ian | S12: Ian | Z12: =COUNTA(B12:Y12)/2 -> 7
D13: Jonathan Mather | E13: Jonathan Mather | F13: Jonathan Mather | G13: Jonathan Mather | H13: Jonathan Mather | I13: Jonathan Mather | J13: Jonathan Mather | K13: Jonathan Mather | Z13: =COUNTA(B13:Y13)/2 -> 4
A14: Wednesday | E14: Hayden | F14: Hayden | H14: Mike | I14: Mike | J14: Mike | K14: Mike | L14: Mike | M14: Mike | N14: Mike | O14: Mike | R14: Chance | S14: Chance | T14: Chance | U14: Chance | Z14: =COUNTA(B14:Y14)/2 -> 7
H15: Zach | I15: Zach | J15: Zach | K15: Zach | L15: Charlie | M15: Charlie | N15: Charlie | P15: Zach | Q15: Zach | R15: Zach | S15: Zach | T15: Khai | U15: Khai | Z15: =COUNTA(B15:Y15)/2 -> 6.5
D16: Emmet | E16: Emmet | F16: Emmet | G16: Emmet | H16: Emmet | I16: Emmet | N16: Hayden | O16: Hayden | P16: Hayden | Q16: Hayden | T16: Ian | U16: Ian | Z16: =COUNTA(B16:Y16)/2 -> 6
F17: Mario Q | G17: Mario Q | K17: Mario Q | L17: Mario Q | M17: Mario Q | N17: Mario Q | Z17: =COUNTA(B17:Y17)/2 -> 3
H18: Aaron | I18: Aaron | J18: Aaron | K18: Aaron | L18: Aaron | M18: Aaron | N18: Aaron | O18: Aaron | Z18: =COUNTA(B18:Y18)/2 -> 4
I19: Jarren | J19: Jarren | K19: Jarren | L19: Jarren | M19: Mario S | N19: Mario S | O19: Mario S | P19: Mario S | Q19: Mario S | R19: Mario S | Z19: =COUNTA(B19:Y19)/2 -> 5
L20: Cameron | M20: Cameron | N20: Cameron | O20: Cameron | P20: Cameron | Q20: Cameron | R20: Cameron | S20: Cameron | Z20: =COUNTA(B20:Y20)/2 -> 4
A21: Thursday | D21: Allen | E21: Allen | F21: Allen | G21: Allen | H21: Allen | I21: Allen | J21: Allen | K21: Allen | P21: Hayden | Q21: Hayden | T21: Jonathan Mach | U21: Jonathan Mach | Z21: =COUNTA(B21:Y21)/2 -> 6
J22: Chance | K22: Chance | L22: Chance | M22: Chance | N22: Jackson | O22: Jackson | P22: Jackson | Q22: Jackson | Z22: =COUNTA(B22:Y22)/2 -> 4
H23: Charlie | I23: Charlie | J23: Charlie | K23: Charlie | M23: Jarren | N23: Jarren | O23: Jarren | P23: Jarren | Z23: =COUNTA(B23:Y23)/2 -> 4
F24: Kyle | G24: Kyle | H24: Kyle | I24: Kyle | J24: Kyle | K24: Kyle | L24: Kyle | M24: Kyle | N24: Ian | O24: Ian | P24: Ian | Q24: Ian | R24: Ian | S24: Ian | Z24: =COUNTA(B24:Y24)/2 -> 7
D25: Jonathan Mather | E25: Jonathan Mather | F25: Jonathan Mather | G25: Jonathan Mather | H25: Jonathan Mather | I25: Jonathan Mather | J25: Jonathan Mather | K25: Jonathan Mather | Z25: =COUNTA(B25:Y25)/2 -> 4
A26: Friday | D26: Emmet | E26: Emmet | F26: Emmet | G26: Emmet | L26: Ian | M26: Ian | P26: Jackson | Q26: Jackson | R26: Jackson | S26: Jackson | Z26: =COUNTA(B26:Y26)/2 -> 5
D27: David | E27: David | F27: David | G27: David | L27: David | M27: David | N27: David | O27: David | P27: David | Q27: David | R27: David | S27: David | T27: David | U27: David | V27: David | W27: David | Z27: =COUNTA(B27:Y27)/2 -> 8
L28: Charlie | M28: Charlie | Z28: =COUNTA(B28:Y28)/2 -> 1
L29: Mario Q | M29: Mario Q | N29: Mario Q | O29: Mario Q | P29: Mario Q | Q29: Mario Q | R29: Mario Q | S29: Mario Q | Z29: =COUNTA(B29:Y29)/2 -> 4
L30: Khai | M30: Khai | N30: Khai | O30: Khai | P30: Khai | Q30: Khai | R30: Khai | S30: Khai | Z30: =COUNTA(B30:Y30)/2 -> 4
A32: Yes
A33: Monday | D33: Mario Q | E33: Mario Q | I33: Jonah | J33: Jonah | K33: Jonah | L33: Jonah | M33: Jonah | N33: Jonah
A34: Tuesday | K34: Jonah | L34: Jonah | M34: Jonah | N34: Jonah | O34: Jonah | P34: Jonah | R34: Jackson | S34: Jackson
A35: Wednesday | I35: Jonah | J35: Jonah | K35: Jonah | L35: Jonah
A36: Thursday | L36: Mario S | M36: Mario S | N36: Mario S | O36: Mario S | R36: Jackson | S36: Jackson
A37: Friday
A39: Count
A40: Monday | B40: =COUNTA(B2:B7,B33) -> 0 | C40: =COUNTA(C2:C7,C33) -> 0 | D40: =COUNTA(D2:D7,D33) -> 2 | E40: =COUNTA(E2:E7,E33) -> 3 | F40: =COUNTA(F2:F7,F33) -> 2 | G40: =COUNTA(G2:G7,G33) -> 1 | H40: =COUNTA(H2:H7,H33) -> 4 | I40: =COUNTA(I2:I7,I33) -> 6 | ... Y40: =COUNTA(Y2:Y7,Y33) -> 1
A41: Tuesday | B41: =COUNTA(B8:B13,B34) -> 0 | C41: =COUNTA(C8:C13,C34) -> 0 | D41: =COUNTA(D8:D13,D34) -> 2 | E41: =COUNTA(E8:E13,E34) -> 2 | F41: =COUNTA(F8:F13,F34) -> 3 | G41: =COUNTA(G8:G13,G34) -> 3 | H41: =COUNTA(H8:H13,H34) -> 5 | I41: =COUNTA(I8:I13,I34) -> 5 | ... Y41: =COUNTA(Y8:Y13,Y34) -> 0
A42: Wednesday | B42: =COUNTA(B14:B20,B35) -> 0 | C42: =COUNTA(C14:C20,C35) -> 0 | D42: =COUNTA(D14:D20,D35) -> 1 | E42: =COUNTA(E14:E20,E35) -> 2 | F42: =COUNTA(F14:F20,F35) -> 3 | G42: =COUNTA(G14:G20,G35) -> 2 | H42: =COUNTA(H14:H20,H35) -> 4 | I42: =COUNTA(I14:I20,I35) -> 6 | ... U42: =COUNTA(U14:U20,U35) -> 3
...

Sheet Summary
A3: Pref | B3: 7:00 - 7:30 | C3: 7:30 - 8:00 | D3: 8:00 - 8:30 | E3: 8:30 - 9:00 | F3: 9:00 - 9:30 | G3: 9:30 - 10:00 | H3: 10:00 - 10:30 | I3: 10:30 - 11:00 | J3: 11:00 - 11:30 | K3: 11:30 - 12:00 | L3: 12:00 - 12:30 | M3: 12:30 - 1:00 | N3: 1:00 - 1:30 | O3: 1:30 - 2:00 | P3: 2:00 - 2:30 | Q3: 2:30 - 3:00 | R3: 3:00 - 3:30 | S3: 3:30 - 4:00 | T3: 4:00 - 4:30 | U3: 4:30 - 5:00 | V3: 5:00 - 5:30 | W3: 5:30 - 6:00 | X3: 6:00 - 6:30 | Y3: 6:30 - 7:00
A4: Monday | B4: =SUM(Allen!B22,Mike!B22,Jonah!B22,Jarren!B22,Chance!B22,'Jonathan Mach'!B22,Zach!B22,Hayden!B22,Kyle!B22,'Jonathan Mather'!B22,Cameron!B22,Emmet!B22,Jackson!B22,Khai!B22,'Mario Q'!B22,Aaron!B22,Ian!B22,Charlie!B22,'Mario S'!B22,David!B22) -> 0 | C4: =SUM(Allen!C22,Mike!C22,Jonah!C22,Jarren!C22,Chance!C22,'Jonathan Mach'!C22,Zach!C22,Hayden!C22,Kyle!C22,'Jonathan Mather'!C22,Cameron!C22,Emmet!C22,Jackson!C22,Khai!C22,'Mario Q'!C22,Aaron!C22,Ian!C22,Charlie!C22,'Mario S'!C22,David!C22) -> 0 | D4: =SUM(Allen!D22,Mike!D22,Jonah!D22,Jarren!D22,Chance!D22,'Jonathan Mach'!D22,Zach!D22,Hayden!D22,Kyle!D22,'Jonathan Mather'!D22,Cameron!D22,Emmet!D22,Jackson!D22,Khai!D22,'Mario Q'!D22,Aaron!D22,Ian!D22,Charlie!D22,'Mario S'!D22,David!D22) -> 1 | E4: =SUM(Allen!E22,Mike!E22,Jonah!E22,Jarren!E22,Chance!E22,'Jonathan Mach'!E22,Zach!E22,Hayden!E22,Kyle!E22,'Jonathan Mather'!E22,Cameron!E22,Emmet!E22,Jackson!E22,Khai!E22,'Mario Q'!E22,Aaron!E22,Ian!E22,Charlie!E22,'Mario S'!E22,David!E22) -> 2 | F4: =SUM(Allen!F22,Mike!F22,Jonah!F22,Jarren!F22,Chance!F22,'Jonathan Mach'!F22,Zach!F22,Hayden!F22,Kyle!F22,'Jonathan Mather'!F22,Cameron!F22,Emmet!F22,Jackson!F22,Khai!F22,'Mario Q'!F22,Aaron!F22,Ian!F22,Charlie!F22,'Mario S'!F22,David!F22) -> 2 | G4: =SUM(Allen!G22,Mike!G22,Jonah!G22,Jarren!G22,Chance!G22,'Jonathan Mach'!G22,Zach!G22,Hayden!G22,Kyle!G22,'Jonathan Mather'!G22,Cameron!G22,Emmet!G22,Jackson!G22,Khai!G22,'Mario Q'!G22,Aaron!G22,Ian!G22,Charlie!G22,'Mario S'!G22,David!G22) -> 1 | H4: =SUM(Allen!H22,Mike!H22,Jonah!H22,Jarren!H22,Chance!H22,'Jonathan Mach'!H22,Zach!H22,Hayden!H22,Kyle!H22,'Jonathan Mather'!H22,Cameron!H22,Emmet!H22,Jackson!H22,Khai!H22,'Mario Q'!H22,Aaron!H22,Ian!H22,Charlie!H22,'Mario S'!H22,David!H22) -> 5 | I4: =SUM(Allen!I22,Mike!I22,Jonah!I22,Jarren!I22,Chance!I22,'Jonathan Mach'!I22,Zach!I22,Hayden!I22,Kyle!I22,'Jonathan Mather'!I22,Cameron!I22,Emmet!I22,Jackson!I22,Khai!I22,'Mario Q'!I22,Aaron!I22,Ian!I22,Charlie!I22,'Mario S'!I22,David!I22) -> 5 | ... Y4: =SUM(Allen!Y22,Mike!Y22,Jonah!Y22,Jarren!Y22,Chance!Y22,'Jonathan Mach'!Y22,Zach!Y22,Hayden!Y22,Kyle!Y22,'Jonathan Mather'!Y22,Cameron!Y22,Emmet!Y22,Jackson!Y22,Khai!Y22,'Mario Q'!Y22,Aaron!Y22,Ian!Y22,Charlie!Y22,'Mario S'!Y22,David!Y22) -> 1
A5: Tuesday | B5: =SUM(Allen!B23,Mike!B23,Jonah!B23,Jarren!B23,Chance!B23,'Jonathan Mach'!B23,Zach!B23,Hayden!B23,Kyle!B23,'Jonathan Mather'!B23,Cameron!B23,Emmet!B23,Jackson!B23,Khai!B23,'Mario Q'!B23,Aaron!B23,Ian!B23,Charlie!B23,'Mario S'!B23,David!B23) -> 0 | C5: =SUM(Allen!C23,Mike!C23,Jonah!C23,Jarren!C23,Chance!C23,'Jonathan Mach'!C23,Zach!C23,Hayden!C23,Kyle!C23,'Jonathan Mather'!C23,Cameron!C23,Emmet!C23,Jackson!C23,Khai!C23,'Mario Q'!C23,Aaron!C23,Ian!C23,Charlie!C23,'Mario S'!C23,David!C23) -> 0 | D5: =SUM(Allen!D23,Mike!D23,Jonah!D23,Jarren!D23,Chance!D23,'Jonathan Mach'!D23,Zach!D23,Hayden!D23,Kyle!D23,'Jonathan Mather'!D23,Cameron!D23,Emmet!D23,Jackson!D23,Khai!D23,'Mario Q'!D23,Aaron!D23,Ian!D23,Charlie!D23,'Mario S'!D23,David!D23) -> 3 | E5: =SUM(Allen!E23,Mike!E23,Jonah!E23,Jarren!E23,Chance!E23,'Jonathan Mach'!E23,Zach!E23,Hayden!E23,Kyle!E23,'Jonathan Mather'!E23,Cameron!E23,Emmet!E23,Jackson!E23,Khai!E23,'Mario Q'!E23,Aaron!E23,Ian!E23,Charlie!E23,'Mario S'!E23,David!E23) -> 3 | F5: =SUM(Allen!F23,Mike!F23,Jonah!F23,Jarren!F23,Chance!F23,'Jonathan Mach'!F23,Zach!F23,Hayden!F23,Kyle!F23,'Jonathan Mather'!F23,Cameron!F23,Emmet!F23,Jackson!F23,Khai!F23,'Mario Q'!F23,Aaron!F23,Ian!F23,Charlie!F23,'Mario S'!F23,David!F23) -> 4 | G5: =SUM(Allen!G23,Mike!G23,Jonah!G23,Jarren!G23,Chance!G23,'Jonathan Mach'!G23,Zach!G23,Hayden!G23,Kyle!G23,'Jonathan Mather'!G23,Cameron!G23,Emmet!G23,Jackson!G23,Khai!G23,'Mario Q'!G23,Aaron!G23,Ian!G23,Charlie!G23,'Mario S'!G23,David!G23) -> 4 | H5: =SUM(Allen!H23,Mike!H23,Jonah!H23,Jarren!H23,Chance!H23,'Jonathan Mach'!H23,Zach!H23,Hayden!H23,Kyle!H23,'Jonathan Mather'!H23,Cameron!H23,Emmet!H23,Jackson!H23,Khai!H23,'Mario Q'!H23,Aaron!H23,Ian!H23,Charlie!H23,'Mario S'!H23,David!H23) -> 5 | I5: =SUM(Allen!I23,Mike!I23,Jonah!I23,Jarren!I23,Chance!I23,'Jonathan Mach'!I23,Zach!I23,Hayden!I23,Kyle!I23,'Jonathan Mather'!I23,Cameron!I23,Emmet!I23,Jackson!I23,Khai!I23,'Mario Q'!I23,Aaron!I23,Ian!I23,Charlie!I23,'Mario S'!I23,David!I23) -> 5 | ... Y5: =SUM(Allen!Y23,Mike!Y23,Jonah!Y23,Jarren!Y23,Chance!Y23,'Jonathan Mach'!Y23,Zach!Y23,Hayden!Y23,Kyle!Y23,'Jonathan Mather'!Y23,Cameron!Y23,Emmet!Y23,Jackson!Y23,Khai!Y23,'Mario Q'!Y23,Aaron!Y23,Ian!Y23,Charlie!Y23,'Mario S'!Y23,David!Y23) -> 0
A6: Wednesday | B6: =SUM(Allen!B24,Mike!B24,Jonah!B24,Jarren!B24,Chance!B24,'Jonathan Mach'!B24,Zach!B24,Hayden!B24,Kyle!B24,'Jonathan Mather'!B24,Cameron!B24,Emmet!B24,Jackson!B24,Khai!B24,'Mario Q'!B24,Aaron!B24,Ian!B24,Charlie!B24,'Mario S'!B24,David!B24) -> 0 | C6: =SUM(Allen!C24,Mike!C24,Jonah!C24,Jarren!C24,Chance!C24,'Jonathan Mach'!C24,Zach!C24,Hayden!C24,Kyle!C24,'Jonathan Mather'!C24,Cameron!C24,Emmet!C24,Jackson!C24,Khai!C24,'Mario Q'!C24,Aaron!C24,Ian!C24,Charlie!C24,'Mario S'!C24,David!C24) -> 0 | D6: =SUM(Allen!D24,Mike!D24,Jonah!D24,Jarren!D24,Chance!D24,'Jonathan Mach'!D24,Zach!D24,Hayden!D24,Kyle!D24,'Jonathan Mather'!D24,Cameron!D24,Emmet!D24,Jackson!D24,Khai!D24,'Mario Q'!D24,Aaron!D24,Ian!D24,Charlie!D24,'Mario S'!D24,David!D24) -> 1 | E6: =SUM(Allen!E24,Mike!E24,Jonah!E24,Jarren!E24,Chance!E24,'Jonathan Mach'!E24,Zach!E24,Hayden!E24,Kyle!E24,'Jonathan Mather'!E24,Cameron!E24,Emmet!E24,Jackson!E24,Khai!E24,'Mario Q'!E24,Aaron!E24,Ian!E24,Charlie!E24,'Mario S'!E24,David!E24) -> 2 | F6: =SUM(Allen!F24,Mike!F24,Jonah!F24,Jarren!F24,Chance!F24,'Jonathan Mach'!F24,Zach!F24,Hayden!F24,Kyle!F24,'Jonathan Mather'!F24,Cameron!F24,Emmet!F24,Jackson!F24,Khai!F24,'Mario Q'!F24,Aaron!F24,Ian!F24,Charlie!F24,'Mario S'!F24,David!F24) -> 3 | G6: =SUM(Allen!G24,Mike!G24,Jonah!G24,Jarren!G24,Chance!G24,'Jonathan Mach'!G24,Zach!G24,Hayden!G24,Kyle!G24,'Jonathan Mather'!G24,Cameron!G24,Emmet!G24,Jackson!G24,Khai!G24,'Mario Q'!G24,Aaron!G24,Ian!G24,Charlie!G24,'Mario S'!G24,David!G24) -> 2 | H6: =SUM(Allen!H24,Mike!H24,Jonah!H24,Jarren!H24,Chance!H24,'Jonathan Mach'!H24,Zach!H24,Hayden!H24,Kyle!H24,'Jonathan Mather'!H24,Cameron!H24,Emmet!H24,Jackson!H24,Khai!H24,'Mario Q'!H24,Aaron!H24,Ian!H24,Charlie!H24,'Mario S'!H24,David!H24) -> 6 | I6: =SUM(Allen!I24,Mike!I24,Jonah!I24,Jarren!I24,Chance!I24,'Jonathan Mach'!I24,Zach!I24,Hayden!I24,Kyle!I24,'Jonathan Mather'!I24,Cameron!I24,Emmet!I24,Jackson!I24,Khai!I24,'Mario Q'!I24,Aaron!I24,Ian!I24,Charlie!I24,'Mario S'!I24,David!I24) -> 6 | ... U6: =SUM(Allen!U24,Mike!U24,Jonah!U24,Jarren!U24,Chance!U24,'Jonathan Mach'!U24,Zach!U24,Hayden!U24,Kyle!U24,'Jonathan Mather'!U24,Cameron!U24,Emmet!U24,Jackson!U24,Khai!U24,'Mario Q'!U24,Aaron!U24,Ian!U24,Charlie!U24,'Mario S'!U24,David!U24) -> 4
A7: Thursday | B7: =SUM(Allen!B25,Mike!B25,Jonah!B25,Jarren!B25,Chance!B25,'Jonathan Mach'!B25,Zach!B25,Hayden!B25,Kyle!B25,'Jonathan Mather'!B25,Cameron!B25,Emmet!B25,Jackson!B25,Khai!B25,'Mario Q'!B25,Aaron!B25,Ian!B25,Charlie!B25,'Mario S'!B25,David!B25) -> 0 | C7: =SUM(Allen!C25,Mike!C25,Jonah!C25,Jarren!C25,Chance!C25,'Jonathan Mach'!C25,Zach!C25,Hayden!C25,Kyle!C25,'Jonathan Mather'!C25,Cameron!C25,Emmet!C25,Jackson!C25,Khai!C25,'Mario Q'!C25,Aaron!C25,Ian!C25,Charlie!C25,'Mario S'!C25,David!C25) -> 0 | D7: =SUM(Allen!D25,Mike!D25,Jonah!D25,Jarren!D25,Chance!D25,'Jonathan Mach'!D25,Zach!D25,Hayden!D25,Kyle!D25,'Jonathan Mather'!D25,Cameron!D25,Emmet!D25,Jackson!D25,Khai!D25,'Mario Q'!D25,Aaron!D25,Ian!D25,Charlie!D25,'Mario S'!D25,David!D25) -> 3 | E7: =SUM(Allen!E25,Mike!E25,Jonah!E25,Jarren!E25,Chance!E25,'Jonathan Mach'!E25,Zach!E25,Hayden!E25,Kyle!E25,'Jonathan Mather'!E25,Cameron!E25,Emmet!E25,Jackson!E25,Khai!E25,'Mario Q'!E25,Aaron!E25,Ian!E25,Charlie!E25,'Mario S'!E25,David!E25) -> 3 | F7: =SUM(Allen!F25,Mike!F25,Jonah!F25,Jarren!F25,Chance!F25,'Jonathan Mach'!F25,Zach!F25,Hayden!F25,Kyle!F25,'Jonathan Mather'!F25,Cameron!F25,Emmet!F25,Jackson!F25,Khai!F25,'Mario Q'!F25,Aaron!F25,Ian!F25,Charlie!F25,'Mario S'!F25,David!F25) -> 4 | G7: =SUM(Allen!G25,Mike!G25,Jonah!G25,Jarren!G25,Chance!G25,'Jonathan Mach'!G25,Zach!G25,Hayden!G25,Kyle!G25,'Jonathan Mather'!G25,Cameron!G25,Emmet!G25,Jackson!G25,Khai!G25,'Mario Q'!G25,Aaron!G25,Ian!G25,Charlie!G25,'Mario S'!G25,David!G25) -> 4 | H7: =SUM(Allen!H25,Mike!H25,Jonah!H25,Jarren!H25,Chance!H25,'Jonathan Mach'!H25,Zach!H25,Hayden!H25,Kyle!H25,'Jonathan Mather'!H25,Cameron!H25,Emmet!H25,Jackson!H25,Khai!H25,'Mario Q'!H25,Aaron!H25,Ian!H25,Charlie!H25,'Mario S'!H25,David!H25) -> 5 | I7: =SUM(Allen!I25,Mike!I25,Jonah!I25,Jarren!I25,Chance!I25,'Jonathan Mach'!I25,Zach!I25,Hayden!I25,Kyle!I25,'Jonathan Mather'!I25,Cameron!I25,Emmet!I25,Jackson!I25,Khai!I25,'Mario Q'!I25,Aaron!I25,Ian!I25,Charlie!I25,'Mario S'!I25,David!I25) -> 5 | ... Y7: =SUM(Allen!Y25,Mike!Y25,Jonah!Y25,Jarren!Y25,Chance!Y25,'Jonathan Mach'!Y25,Zach!Y25,Hayden!Y25,Kyle!Y25,'Jonathan Mather'!Y25,Cameron!Y25,Emmet!Y25,Jackson!Y25,Khai!Y25,'Mario Q'!Y25,Aaron!Y25,Ian!Y25,Charlie!Y25,'Mario S'!Y25,David!Y25) -> 0
A8: Friday | B8: =SUM(Allen!B26,Mike!B26,Jonah!B26,Jarren!B26,Chance!B26,'Jonathan Mach'!B26,Zach!B26,Hayden!B26,Kyle!B26,'Jonathan Mather'!B26,Cameron!B26,Emmet!B26,Jackson!B26,Khai!B26,'Mario Q'!B26,Aaron!B26,Ian!B26,Charlie!B26,'Mario S'!B26,David!B26) -> 0 | C8: =SUM(Allen!C26,Mike!C26,Jonah!C26,Jarren!C26,Chance!C26,'Jonathan Mach'!C26,Zach!C26,Hayden!C26,Kyle!C26,'Jonathan Mather'!C26,Cameron!C26,Emmet!C26,Jackson!C26,Khai!C26,'Mario Q'!C26,Aaron!C26,Ian!C26,Charlie!C26,'Mario S'!C26,David!C26) -> 0 | D8: =SUM(Allen!D26,Mike!D26,Jonah!D26,Jarren!D26,Chance!D26,'Jonathan Mach'!D26,Zach!D26,Hayden!D26,Kyle!D26,'Jonathan Mather'!D26,Cameron!D26,Emmet!D26,Jackson!D26,Khai!D26,'Mario Q'!D26,Aaron!D26,Ian!D26,Charlie!D26,'Mario S'!D26,David!D26) -> 2 | E8: =SUM(Allen!E26,Mike!E26,Jonah!E26,Jarren!E26,Chance!E26,'Jonathan Mach'!E26,Zach!E26,Hayden!E26,Kyle!E26,'Jonathan Mather'!E26,Cameron!E26,Emmet!E26,Jackson!E26,Khai!E26,'Mario Q'!E26,Aaron!E26,Ian!E26,Charlie!E26,'Mario S'!E26,David!E26) -> 2 | F8: =SUM(Allen!F26,Mike!F26,Jonah!F26,Jarren!F26,Chance!F26,'Jonathan Mach'!F26,Zach!F26,Hayden!F26,Kyle!F26,'Jonathan Mather'!F26,Cameron!F26,Emmet!F26,Jackson!F26,Khai!F26,'Mario Q'!F26,Aaron!F26,Ian!F26,Charlie!F26,'Mario S'!F26,David!F26) -> 2 | G8: =SUM(Allen!G26,Mike!G26,Jonah!G26,Jarren!G26,Chance!G26,'Jonathan Mach'!G26,Zach!G26,Hayden!G26,Kyle!G26,'Jonathan Mather'!G26,Cameron!G26,Emmet!G26,Jackson!G26,Khai!G26,'Mario Q'!G26,Aaron!G26,Ian!G26,Charlie!G26,'Mario S'!G26,David!G26) -> 2 | L8: =SUM(Allen!L26,Mike!L26,Jonah!L26,Jarren!L26,Chance!L26,'Jonathan Mach'!L26,Zach!L26,Hayden!L26,Kyle!L26,'Jonathan Mather'!L26,Cameron!L26,Emmet!L26,Jackson!L26,Khai!L26,'Mario Q'!L26,Aaron!L26,Ian!L26,Charlie!L26,'Mario S'!L26,David!L26) -> 5 | M8: =SUM(Allen!M26,Mike!M26,Jonah!M26,Jarren!M26,Chance!M26,'Jonathan Mach'!M26,Zach!M26,Hayden!M26,Kyle!M26,'Jonathan Mather'!M26,Cameron!M26,Emmet!M26,Jackson!M26,Khai!M26,'Mario Q'!M26,Aaron!M26,Ian!M26,Charlie!M26,'Mario S'!M26,David!M26) -> 5 | N8: =SUM(Allen!N26,Mike!N26,Jonah!N26,Jarren!N26,Chance!N26,'Jonathan Mach'!N26,Zach!N26,Hayden!N26,Kyle!N26,'Jonathan Mather'!N26,Cameron!N26,Emmet!N26,Jackson!N26,Khai!N26,'Mario Q'!N26,Aaron!N26,Ian!N26,Charlie!N26,'Mario S'!N26,David!N26) -> 3 | O8: =SUM(Allen!O26,Mike!O26,Jonah!O26,Jarren!O26,Chance!O26,'Jonathan Mach'!O26,Zach!O26,Hayden!O26,Kyle!O26,'Jonathan Mather'!O26,Cameron!O26,Emmet!O26,Jackson!O26,Khai!O26,'Mario Q'!O26,Aaron!O26,Ian!O26,Charlie!O26,'Mario S'!O26,David!O26) -> 3 | P8: =SUM(Allen!P26,Mike!P26,Jonah!P26,Jarren!P26,Chance!P26,'Jonathan Mach'!P26,Zach!P26,Hayden!P26,Kyle!P26,'Jonathan Mather'!P26,Cameron!P26,Emmet!P26,Jackson!P26,Khai!P26,'Mario Q'!P26,Aaron!P26,Ian!P26,Charlie!P26,'Mario S'!P26,David!P26) -> 4 | Q8: =SUM(Allen!Q26,Mike!Q26,Jonah!Q26,Jarren!Q26,Chance!Q26,'Jonathan Mach'!Q26,Zach!Q26,Hayden!Q26,Kyle!Q26,'Jonathan Mather'!Q26,Cameron!Q26,Emmet!Q26,Jackson!Q26,Khai!Q26,'Mario Q'!Q26,Aaron!Q26,Ian!Q26,Charlie!Q26,'Mario S'!Q26,David!Q26) -> 4 | R8: =SUM(Allen!R26,Mike!R26,Jonah!R26,Jarren!R26,Chance!R26,'Jonathan Mach'!R26,Zach!R26,Hayden!R26,Kyle!R26,'Jonathan Mather'!R26,Cameron!R26,Emmet!R26,Jackson!R26,Khai!R26,'Mario Q'!R26,Aaron!R26,Ian!R26,Charlie!R26,'Mario S'!R26,David!R26) -> 4 | S8: =SUM(Allen!S26,Mike!S26,Jonah!S26,Jarren!S26,Chance!S26,'Jonathan Mach'!S26,Zach!S26,Hayden!S26,Kyle!S26,'Jonathan Mather'!S26,Cameron!S26,Emmet!S26,Jackson!S26,Khai!S26,'Mario Q'!S26,Aaron!S26,Ian!S26,Charlie!S26,'Mario S'!S26,David!S26) -> 4 | ... Y8: =SUM(Allen!Y26,Mike!Y26,Jonah!Y26,Jarren!Y26,Chance!Y26,'Jonathan Mach'!Y26,Zach!Y26,Hayden!Y26,Kyle!Y26,'Jonathan Mather'!Y26,Cameron!Y26,Emmet!Y26,Jackson!Y26,Khai!Y26,'Mario Q'!Y26,Aaron!Y26,Ian!Y26,Charlie!Y26,'Mario S'!Y26,David!Y26) -> 0
A9: =MAX(B4:Y8) -> 8
A10: Yes
A11: Monday | B11: =SUM(Allen!B29,Mike!B29,Jonah!B29,Jarren!B29,Chance!B29,'Jonathan Mach'!B29,Zach!B29,Hayden!B29,Kyle!B29,'Jonathan Mather'!B29,Cameron!B29,Emmet!B29,Jackson!B29,Khai!B29,'Mario Q'!B29,Aaron!B29,Ian!B29,Charlie!B29,'Mario S'!B29,David!B29) -> 3 | C11: =SUM(Allen!C29,Mike!C29,Jonah!C29,Jarren!C29,Chance!C29,'Jonathan Mach'!C29,Zach!C29,Hayden!C29,Kyle!C29,'Jonathan Mather'!C29,Cameron!C29,Emmet!C29,Jackson!C29,Khai!C29,'Mario Q'!C29,Aaron!C29,Ian!C29,Charlie!C29,'Mario S'!C29,David!C29) -> 3 | D11: =SUM(Allen!D29,Mike!D29,Jonah!D29,Jarren!D29,Chance!D29,'Jonathan Mach'!D29,Zach!D29,Hayden!D29,Kyle!D29,'Jonathan Mather'!D29,Cameron!D29,Emmet!D29,Jackson!D29,Khai!D29,'Mario Q'!D29,Aaron!D29,Ian!D29,Charlie!D29,'Mario S'!D29,David!D29) -> 5 | E11: =SUM(Allen!E29,Mike!E29,Jonah!E29,Jarren!E29,Chance!E29,'Jonathan Mach'!E29,Zach!E29,Hayden!E29,Kyle!E29,'Jonathan Mather'!E29,Cameron!E29,Emmet!E29,Jackson!E29,Khai!E29,'Mario Q'!E29,Aaron!E29,Ian!E29,Charlie!E29,'Mario S'!E29,David!E29) -> 5 | F11: =SUM(Allen!F29,Mike!F29,Jonah!F29,Jarren!F29,Chance!F29,'Jonathan Mach'!F29,Zach!F29,Hayden!F29,Kyle!F29,'Jonathan Mather'!F29,Cameron!F29,Emmet!F29,Jackson!F29,Khai!F29,'Mario Q'!F29,Aaron!F29,Ian!F29,Charlie!F29,'Mario S'!F29,David!F29) -> 3 | G11: =SUM(Allen!G29,Mike!G29,Jonah!G29,Jarren!G29,Chance!G29,'Jonathan Mach'!G29,Zach!G29,Hayden!G29,Kyle!G29,'Jonathan Mather'!G29,Cameron!G29,Emmet!G29,Jackson!G29,Khai!G29,'Mario Q'!G29,Aaron!G29,Ian!G29,Charlie!G29,'Mario S'!G29,David!G29) -> 2 | H11: =SUM(Allen!H29,Mike!H29,Jonah!H29,Jarren!H29,Chance!H29,'Jonathan Mach'!H29,Zach!H29,Hayden!H29,Kyle!H29,'Jonathan Mather'!H29,Cameron!H29,Emmet!H29,Jackson!H29,Khai!H29,'Mario Q'!H29,Aaron!H29,Ian!H29,Charlie!H29,'Mario S'!H29,David!H29) -> 1 | I11: =SUM(Allen!I29,Mike!I29,Jonah!I29,Jarren!I29,Chance!I29,'Jonathan Mach'!I29,Zach!I29,Hayden!I29,Kyle!I29,'Jonathan Mather'!I29,Cameron!I29,Emmet!I29,Jackson!I29,Khai!I29,'Mario Q'!I29,Aaron!I29,Ian!I29,Charlie!I29,'Mario S'!I29,David!I29) -> 2 | ... Y11: =SUM(Allen!Y29,Mike!Y29,Jonah!Y29,Jarren!Y29,Chance!Y29,'Jonathan Mach'!Y29,Zach!Y29,Hayden!Y29,Kyle!Y29,'Jonathan Mather'!Y29,Cameron!Y29,Emmet!Y29,Jackson!Y29,Khai!Y29,'Mario Q'!Y29,Aaron!Y29,Ian!Y29,Charlie!Y29,'Mario S'!Y29,David!Y29) -> 1
A12: Tuesday | B12: =SUM(Allen!B30,Mike!B30,Jonah!B30,Jarren!B30,Chance!B30,'Jonathan Mach'!B30,Zach!B30,Hayden!B30,Kyle!B30,'Jonathan Mather'!B30,Cameron!B30,Emmet!B30,Jackson!B30,Khai!B30,'Mario Q'!B30,Aaron!B30,Ian!B30,Charlie!B30,'Mario S'!B30,David!B30) -> 3 | C12: =SUM(Allen!C30,Mike!C30,Jonah!C30,Jarren!C30,Chance!C30,'Jonathan Mach'!C30,Zach!C30,Hayden!C30,Kyle!C30,'Jonathan Mather'!C30,Cameron!C30,Emmet!C30,Jackson!C30,Khai!C30,'Mario Q'!C30,Aaron!C30,Ian!C30,Charlie!C30,'Mario S'!C30,David!C30) -> 3 | D12: =SUM(Allen!D30,Mike!D30,Jonah!D30,Jarren!D30,Chance!D30,'Jonathan Mach'!D30,Zach!D30,Hayden!D30,Kyle!D30,'Jonathan Mather'!D30,Cameron!D30,Emmet!D30,Jackson!D30,Khai!D30,'Mario Q'!D30,Aaron!D30,Ian!D30,Charlie!D30,'Mario S'!D30,David!D30) -> 1 | E12: =SUM(Allen!E30,Mike!E30,Jonah!E30,Jarren!E30,Chance!E30,'Jonathan Mach'!E30,Zach!E30,Hayden!E30,Kyle!E30,'Jonathan Mather'!E30,Cameron!E30,Emmet!E30,Jackson!E30,Khai!E30,'Mario Q'!E30,Aaron!E30,Ian!E30,Charlie!E30,'Mario S'!E30,David!E30) -> 1 | F12: =SUM(Allen!F30,Mike!F30,Jonah!F30,Jarren!F30,Chance!F30,'Jonathan Mach'!F30,Zach!F30,Hayden!F30,Kyle!F30,'Jonathan Mather'!F30,Cameron!F30,Emmet!F30,Jackson!F30,Khai!F30,'Mario Q'!F30,Aaron!F30,Ian!F30,Charlie!F30,'Mario S'!F30,David!F30) -> 0 | G12: =SUM(Allen!G30,Mike!G30,Jonah!G30,Jarren!G30,Chance!G30,'Jonathan Mach'!G30,Zach!G30,Hayden!G30,Kyle!G30,'Jonathan Mather'!G30,Cameron!G30,Emmet!G30,Jackson!G30,Khai!G30,'Mario Q'!G30,Aaron!G30,Ian!G30,Charlie!G30,'Mario S'!G30,David!G30) -> 1 | H12: =SUM(Allen!H30,Mike!H30,Jonah!H30,Jarren!H30,Chance!H30,'Jonathan Mach'!H30,Zach!H30,Hayden!H30,Kyle!H30,'Jonathan Mather'!H30,Cameron!H30,Emmet!H30,Jackson!H30,Khai!H30,'Mario Q'!H30,Aaron!H30,Ian!H30,Charlie!H30,'Mario S'!H30,David!H30) -> 6 | I12: =SUM(Allen!I30,Mike!I30,Jonah!I30,Jarren!I30,Chance!I30,'Jonathan Mach'!I30,Zach!I30,Hayden!I30,Kyle!I30,'Jonathan Mather'!I30,Cameron!I30,Emmet!I30,Jackson!I30,Khai!I30,'Mario Q'!I30,Aaron!I30,Ian!I30,Charlie!I30,'Mario S'!I30,David!I30) -> 7 | ... Y12: =SUM(Allen!Y30,Mike!Y30,Jonah!Y30,Jarren!Y30,Chance!Y30,'Jonathan Mach'!Y30,Zach!Y30,Hayden!Y30,Kyle!Y30,'Jonathan Mather'!Y30,Cameron!Y30,Emmet!Y30,Jackson!Y30,Khai!Y30,'Mario Q'!Y30,Aaron!Y30,Ian!Y30,Charlie!Y30,'Mario S'!Y30,David!Y30) -> 2
A13: Wednesday | B13: =SUM(Allen!B31,Mike!B31,Jonah!B31,Jarren!B31,Chance!B31,'Jonathan Mach'!B31,Zach!B31,Hayden!B31,Kyle!B31,'Jonathan Mather'!B31,Cameron!B31,Emmet!B31,Jackson!B31,Khai!B31,'Mario Q'!B31,Aaron!B31,Ian!B31,Charlie!B31,'Mario S'!B31,David!B31) -> 3 | C13: =SUM(Allen!C31,Mike!C31,Jonah!C31,Jarren!C31,Chance!C31,'Jonathan Mach'!C31,Zach!C31,Hayden!C31,Kyle!C31,'Jonathan Mather'!C31,Cameron!C31,Emmet!C31,Jackson!C31,Khai!C31,'Mario Q'!C31,Aaron!C31,Ian!C31,Charlie!C31,'Mario S'!C31,David!C31) -> 3 | D13: =SUM(Allen!D31,Mike!D31,Jonah!D31,Jarren!D31,Chance!D31,'Jonathan Mach'!D31,Zach!D31,Hayden!D31,Kyle!D31,'Jonathan Mather'!D31,Cameron!D31,Emmet!D31,Jackson!D31,Khai!D31,'Mario Q'!D31,Aaron!D31,Ian!D31,Charlie!D31,'Mario S'!D31,David!D31) -> 5 | E13: =SUM(Allen!E31,Mike!E31,Jonah!E31,Jarren!E31,Chance!E31,'Jonathan Mach'!E31,Zach!E31,Hayden!E31,Kyle!E31,'Jonathan Mather'!E31,Cameron!E31,Emmet!E31,Jackson!E31,Khai!E31,'Mario Q'!E31,Aaron!E31,Ian!E31,Charlie!E31,'Mario S'!E31,David!E31) -> 5 | F13: =SUM(Allen!F31,Mike!F31,Jonah!F31,Jarren!F31,Chance!F31,'Jonathan Mach'!F31,Zach!F31,Hayden!F31,Kyle!F31,'Jonathan Mather'!F31,Cameron!F31,Emmet!F31,Jackson!F31,Khai!F31,'Mario Q'!F31,Aaron!F31,Ian!F31,Charlie!F31,'Mario S'!F31,David!F31) -> 3 | G13: =SUM(Allen!G31,Mike!G31,Jonah!G31,Jarren!G31,Chance!G31,'Jonathan Mach'!G31,Zach!G31,Hayden!G31,Kyle!G31,'Jonathan Mather'!G31,Cameron!G31,Emmet!G31,Jackson!G31,Khai!G31,'Mario Q'!G31,Aaron!G31,Ian!G31,Charlie!G31,'Mario S'!G31,David!G31) -> 2 | H13: =SUM(Allen!H31,Mike!H31,Jonah!H31,Jarren!H31,Chance!H31,'Jonathan Mach'!H31,Zach!H31,Hayden!H31,Kyle!H31,'Jonathan Mather'!H31,Cameron!H31,Emmet!H31,Jackson!H31,Khai!H31,'Mario Q'!H31,Aaron!H31,Ian!H31,Charlie!H31,'Mario S'!H31,David!H31) -> 1 | I13: =SUM(Allen!I31,Mike!I31,Jonah!I31,Jarren!I31,Chance!I31,'Jonathan Mach'!I31,Zach!I31,Hayden!I31,Kyle!I31,'Jonathan Mather'!I31,Cameron!I31,Emmet!I31,Jackson!I31,Khai!I31,'Mario Q'!I31,Aaron!I31,Ian!I31,Charlie!I31,'Mario S'!I31,David!I31) -> 2 | ... U13: =SUM(Allen!U31,Mike!U31,Jonah!U31,Jarren!U31,Chance!U31,'Jonathan Mach'!U31,Zach!U31,Hayden!U31,Kyle!U31,'Jonathan Mather'!U31,Cameron!U31,Emmet!U31,Jackson!U31,Khai!U31,'Mario Q'!U31,Aaron!U31,Ian!U31,Charlie!U31,'Mario S'!U31,David!U31) -> 2
A14: Thursday | B14: =SUM(Allen!B32,Mike!B32,Jonah!B32,Jarren!B32,Chance!B32,'Jonathan Mach'!B32,Zach!B32,Hayden!B32,Kyle!B32,'Jonathan Mather'!B32,Cameron!B32,Emmet!B32,Jackson!B32,Khai!B32,'Mario Q'!B32,Aaron!B32,Ian!B32,Charlie!B32,'Mario S'!B32,David!B32) -> 3 | C14: =SUM(Allen!C32,Mike!C32,Jonah!C32,Jarren!C32,Chance!C32,'Jonathan Mach'!C32,Zach!C32,Hayden!C32,Kyle!C32,'Jonathan Mather'!C32,Cameron!C32,Emmet!C32,Jackson!C32,Khai!C32,'Mario Q'!C32,Aaron!C32,Ian!C32,Charlie!C32,'Mario S'!C32,David!C32) -> 3 | D14: =SUM(Allen!D32,Mike!D32,Jonah!D32,Jarren!D32,Chance!D32,'Jonathan Mach'!D32,Zach!D32,Hayden!D32,Kyle!D32,'Jonathan Mather'!D32,Cameron!D32,Emmet!D32,Jackson!D32,Khai!D32,'Mario Q'!D32,Aaron!D32,Ian!D32,Charlie!D32,'Mario S'!D32,David!D32) -> 1 | E14: =SUM(Allen!E32,Mike!E32,Jonah!E32,Jarren!E32,Chance!E32,'Jonathan Mach'!E32,Zach!E32,Hayden!E32,Kyle!E32,'Jonathan Mather'!E32,Cameron!E32,Emmet!E32,Jackson!E32,Khai!E32,'Mario Q'!E32,Aaron!E32,Ian!E32,Charlie!E32,'Mario S'!E32,David!E32) -> 1 | F14: =SUM(Allen!F32,Mike!F32,Jonah!F32,Jarren!F32,Chance!F32,'Jonathan Mach'!F32,Zach!F32,Hayden!F32,Kyle!F32,'Jonathan Mather'!F32,Cameron!F32,Emmet!F32,Jackson!F32,Khai!F32,'Mario Q'!F32,Aaron!F32,Ian!F32,Charlie!F32,'Mario S'!F32,David!F32) -> 0 | G14: =SUM(Allen!G32,Mike!G32,Jonah!G32,Jarren!G32,Chance!G32,'Jonathan Mach'!G32,Zach!G32,Hayden!G32,Kyle!G32,'Jonathan Mather'!G32,Cameron!G32,Emmet!G32,Jackson!G32,Khai!G32,'Mario Q'!G32,Aaron!G32,Ian!G32,Charlie!G32,'Mario S'!G32,David!G32) -> 1 | H14: =SUM(Allen!H32,Mike!H32,Jonah!H32,Jarren!H32,Chance!H32,'Jonathan Mach'!H32,Zach!H32,Hayden!H32,Kyle!H32,'Jonathan Mather'!H32,Cameron!H32,Emmet!H32,Jackson!H32,Khai!H32,'Mario Q'!H32,Aaron!H32,Ian!H32,Charlie!H32,'Mario S'!H32,David!H32) -> 5 | I14: =SUM(Allen!I32,Mike!I32,Jonah!I32,Jarren!I32,Chance!I32,'Jonathan Mach'!I32,Zach!I32,Hayden!I32,Kyle!I32,'Jonathan Mather'!I32,Cameron!I32,Emmet!I32,Jackson!I32,Khai!I32,'Mario Q'!I32,Aaron!I32,Ian!I32,Charlie!I32,'Mario S'!I32,David!I32) -> 5 | ... Y14: =SUM(Allen!Y32,Mike!Y32,Jonah!Y32,Jarren!Y32,Chance!Y32,'Jonathan Mach'!Y32,Zach!Y32,Hayden!Y32,Kyle!Y32,'Jonathan Mather'!Y32,Cameron!Y32,Emmet!Y32,Jackson!Y32,Khai!Y32,'Mario Q'!Y32,Aaron!Y32,Ian!Y32,Charlie!Y32,'Mario S'!Y32,David!Y32) -> 1
A15: Friday | B15: =SUM(Allen!B33,Mike!B33,Jonah!B33,Jarren!B33,Chance!B33,'Jonathan Mach'!B33,Zach!B33,Hayden!B33,Kyle!B33,'Jonathan Mather'!B33,Cameron!B33,Emmet!B33,Jackson!B33,Khai!B33,'Mario Q'!B33,Aaron!B33,Ian!B33,Charlie!B33,'Mario S'!B33,David!B33) -> 3 | C15: =SUM(Allen!C33,Mike!C33,Jonah!C33,Jarren!C33,Chance!C33,'Jonathan Mach'!C33,Zach!C33,Hayden!C33,Kyle!C33,'Jonathan Mather'!C33,Cameron!C33,Emmet!C33,Jackson!C33,Khai!C33,'Mario Q'!C33,Aaron!C33,Ian!C33,Charlie!C33,'Mario S'!C33,David!C33) -> 3 | D15: =SUM(Allen!D33,Mike!D33,Jonah!D33,Jarren!D33,Chance!D33,'Jonathan Mach'!D33,Zach!D33,Hayden!D33,Kyle!D33,'Jonathan Mather'!D33,Cameron!D33,Emmet!D33,Jackson!D33,Khai!D33,'Mario Q'!D33,Aaron!D33,Ian!D33,Charlie!D33,'Mario S'!D33,David!D33) -> 3 | E15: =SUM(Allen!E33,Mike!E33,Jonah!E33,Jarren!E33,Chance!E33,'Jonathan Mach'!E33,Zach!E33,Hayden!E33,Kyle!E33,'Jonathan Mather'!E33,Cameron!E33,Emmet!E33,Jackson!E33,Khai!E33,'Mario Q'!E33,Aaron!E33,Ian!E33,Charlie!E33,'Mario S'!E33,David!E33) -> 3 | F15: =SUM(Allen!F33,Mike!F33,Jonah!F33,Jarren!F33,Chance!F33,'Jonathan Mach'!F33,Zach!F33,Hayden!F33,Kyle!F33,'Jonathan Mather'!F33,Cameron!F33,Emmet!F33,Jackson!F33,Khai!F33,'Mario Q'!F33,Aaron!F33,Ian!F33,Charlie!F33,'Mario S'!F33,David!F33) -> 3 | G15: =SUM(Allen!G33,Mike!G33,Jonah!G33,Jarren!G33,Chance!G33,'Jonathan Mach'!G33,Zach!G33,Hayden!G33,Kyle!G33,'Jonathan Mather'!G33,Cameron!G33,Emmet!G33,Jackson!G33,Khai!G33,'Mario Q'!G33,Aaron!G33,Ian!G33,Charlie!G33,'Mario S'!G33,David!G33) -> 3 | L15: =SUM(Allen!L33,Mike!L33,Jonah!L33,Jarren!L33,Chance!L33,'Jonathan Mach'!L33,Zach!L33,Hayden!L33,Kyle!L33,'Jonathan Mather'!L33,Cameron!L33,Emmet!L33,Jackson!L33,Khai!L33,'Mario Q'!L33,Aaron!L33,Ian!L33,Charlie!L33,'Mario S'!L33,David!L33) -> 3 | M15: =SUM(Allen!M33,Mike!M33,Jonah!M33,Jarren!M33,Chance!M33,'Jonathan Mach'!M33,Zach!M33,Hayden!M33,Kyle!M33,'Jonathan Mather'!M33,Cameron!M33,Emmet!M33,Jackson!M33,Khai!M33,'Mario Q'!M33,Aaron!M33,Ian!M33,Charlie!M33,'Mario S'!M33,David!M33) -> 3 | N15: =SUM(Allen!N33,Mike!N33,Jonah!N33,Jarren!N33,Chance!N33,'Jonathan Mach'!N33,Zach!N33,Hayden!N33,Kyle!N33,'Jonathan Mather'!N33,Cameron!N33,Emmet!N33,Jackson!N33,Khai!N33,'Mario Q'!N33,Aaron!N33,Ian!N33,Charlie!N33,'Mario S'!N33,David!N33) -> 3 | O15: =SUM(Allen!O33,Mike!O33,Jonah!O33,Jarren!O33,Chance!O33,'Jonathan Mach'!O33,Zach!O33,Hayden!O33,Kyle!O33,'Jonathan Mather'!O33,Cameron!O33,Emmet!O33,Jackson!O33,Khai!O33,'Mario Q'!O33,Aaron!O33,Ian!O33,Charlie!O33,'Mario S'!O33,David!O33) -> 2 | P15: =SUM(Allen!P33,Mike!P33,Jonah!P33,Jarren!P33,Chance!P33,'Jonathan Mach'!P33,Zach!P33,Hayden!P33,Kyle!P33,'Jonathan Mather'!P33,Cameron!P33,Emmet!P33,Jackson!P33,Khai!P33,'Mario Q'!P33,Aaron!P33,Ian!P33,Charlie!P33,'Mario S'!P33,David!P33) -> 3 | Q15: =SUM(Allen!Q33,Mike!Q33,Jonah!Q33,Jarren!Q33,Chance!Q33,'Jonathan Mach'!Q33,Zach!Q33,Hayden!Q33,Kyle!Q33,'Jonathan Mather'!Q33,Cameron!Q33,Emmet!Q33,Jackson!Q33,Khai!Q33,'Mario Q'!Q33,Aaron!Q33,Ian!Q33,Charlie!Q33,'Mario S'!Q33,David!Q33) -> 3 | R15: =SUM(Allen!R33,Mike!R33,Jonah!R33,Jarren!R33,Chance!R33,'Jonathan Mach'!R33,Zach!R33,Hayden!R33,Kyle!R33,'Jonathan Mather'!R33,Cameron!R33,Emmet!R33,Jackson!R33,Khai!R33,'Mario Q'!R33,Aaron!R33,Ian!R33,Charlie!R33,'Mario S'!R33,David!R33) -> 2 | S15: =SUM(Allen!S33,Mike!S33,Jonah!S33,Jarren!S33,Chance!S33,'Jonathan Mach'!S33,Zach!S33,Hayden!S33,Kyle!S33,'Jonathan Mather'!S33,Cameron!S33,Emmet!S33,Jackson!S33,Khai!S33,'Mario Q'!S33,Aaron!S33,Ian!S33,Charlie!S33,'Mario S'!S33,David!S33) -> 1 | ... Y15: =SUM(Allen!Y33,Mike!Y33,Jonah!Y33,Jarren!Y33,Chance!Y33,'Jonathan Mach'!Y33,Zach!Y33,Hayden!Y33,Kyle!Y33,'Jonathan Mather'!Y33,Cameron!Y33,Emmet!Y33,Jackson!Y33,Khai!Y33,'Mario Q'!Y33,Aaron!Y33,Ian!Y33,Charlie!Y33,'Mario S'!Y33,David!Y33) -> 1
A17: No
A18: Monday | B18: =SUM(Allen!B36,Mike!B36,Jonah!B36,Jarren!B36,Chance!B36,'Jonathan Mach'!B36,Zach!B36,Hayden!B36,Kyle!B36,'Jonathan Mather'!B36,Cameron!B36,Emmet!B36,Jackson!B36,Khai!B36,'Mario Q'!B36,Aaron!B36,Ian!B36,Charlie!B36,'Mario S'!B36,David!B36) -> 3 | C18: =SUM(Allen!C36,Mike!C36,Jonah!C36,Jarren!C36,Chance!C36,'Jonathan Mach'!C36,Zach!C36,Hayden!C36,Kyle!C36,'Jonathan Mather'!C36,Cameron!C36,Emmet!C36,Jackson!C36,Khai!C36,'Mario Q'!C36,Aaron!C36,Ian!C36,Charlie!C36,'Mario S'!C36,David!C36) -> 3 | D18: =SUM(Allen!D36,Mike!D36,Jonah!D36,Jarren!D36,Chance!D36,'Jonathan Mach'!D36,Zach!D36,Hayden!D36,Kyle!D36,'Jonathan Mather'!D36,Cameron!D36,Emmet!D36,Jackson!D36,Khai!D36,'Mario Q'!D36,Aaron!D36,Ian!D36,Charlie!D36,'Mario S'!D36,David!D36) -> 4 | E18: =SUM(Allen!E36,Mike!E36,Jonah!E36,Jarren!E36,Chance!E36,'Jonathan Mach'!E36,Zach!E36,Hayden!E36,Kyle!E36,'Jonathan Mather'!E36,Cameron!E36,Emmet!E36,Jackson!E36,Khai!E36,'Mario Q'!E36,Aaron!E36,Ian!E36,Charlie!E36,'Mario S'!E36,David!E36) -> 4 | F18: =SUM(Allen!F36,Mike!F36,Jonah!F36,Jarren!F36,Chance!F36,'Jonathan Mach'!F36,Zach!F36,Hayden!F36,Kyle!F36,'Jonathan Mather'!F36,Cameron!F36,Emmet!F36,Jackson!F36,Khai!F36,'Mario Q'!F36,Aaron!F36,Ian!F36,Charlie!F36,'Mario S'!F36,David!F36) -> 4 | G18: =SUM(Allen!G36,Mike!G36,Jonah!G36,Jarren!G36,Chance!G36,'Jonathan Mach'!G36,Zach!G36,Hayden!G36,Kyle!G36,'Jonathan Mather'!G36,Cameron!G36,Emmet!G36,Jackson!G36,Khai!G36,'Mario Q'!G36,Aaron!G36,Ian!G36,Charlie!G36,'Mario S'!G36,David!G36) -> 4 | H18: =SUM(Allen!H36,Mike!H36,Jonah!H36,Jarren!H36,Chance!H36,'Jonathan Mach'!H36,Zach!H36,Hayden!H36,Kyle!H36,'Jonathan Mather'!H36,Cameron!H36,Emmet!H36,Jackson!H36,Khai!H36,'Mario Q'!H36,Aaron!H36,Ian!H36,Charlie!H36,'Mario S'!H36,David!H36) -> 1 | I18: =SUM(Allen!I36,Mike!I36,Jonah!I36,Jarren!I36,Chance!I36,'Jonathan Mach'!I36,Zach!I36,Hayden!I36,Kyle!I36,'Jonathan Mather'!I36,Cameron!I36,Emmet!I36,Jackson!I36,Khai!I36,'Mario Q'!I36,Aaron!I36,Ian!I36,Charlie!I36,'Mario S'!I36,David!I36) -> 1 | ... Y18: =SUM(Allen!Y36,Mike!Y36,Jonah!Y36,Jarren!Y36,Chance!Y36,'Jonathan Mach'!Y36,Zach!Y36,Hayden!Y36,Kyle!Y36,'Jonathan Mather'!Y36,Cameron!Y36,Emmet!Y36,Jackson!Y36,Khai!Y36,'Mario Q'!Y36,Aaron!Y36,Ian!Y36,Charlie!Y36,'Mario S'!Y36,David!Y36) -> 3
A19: Tuesday | B19: =SUM(Allen!B37,Mike!B37,Jonah!B37,Jarren!B37,Chance!B37,'Jonathan Mach'!B37,Zach!B37,Hayden!B37,Kyle!B37,'Jonathan Mather'!B37,Cameron!B37,Emmet!B37,Jackson!B37,Khai!B37,'Mario Q'!B37,Aaron!B37,Ian!B37,Charlie!B37,'Mario S'!B37,David!B37) -> 3 | C19: =SUM(Allen!C37,Mike!C37,Jonah!C37,Jarren!C37,Chance!C37,'Jonathan Mach'!C37,Zach!C37,Hayden!C37,Kyle!C37,'Jonathan Mather'!C37,Cameron!C37,Emmet!C37,Jackson!C37,Khai!C37,'Mario Q'!C37,Aaron!C37,Ian!C37,Charlie!C37,'Mario S'!C37,David!C37) -> 3 | D19: =SUM(Allen!D37,Mike!D37,Jonah!D37,Jarren!D37,Chance!D37,'Jonathan Mach'!D37,Zach!D37,Hayden!D37,Kyle!D37,'Jonathan Mather'!D37,Cameron!D37,Emmet!D37,Jackson!D37,Khai!D37,'Mario Q'!D37,Aaron!D37,Ian!D37,Charlie!D37,'Mario S'!D37,David!D37) -> 3 | E19: =SUM(Allen!E37,Mike!E37,Jonah!E37,Jarren!E37,Chance!E37,'Jonathan Mach'!E37,Zach!E37,Hayden!E37,Kyle!E37,'Jonathan Mather'!E37,Cameron!E37,Emmet!E37,Jackson!E37,Khai!E37,'Mario Q'!E37,Aaron!E37,Ian!E37,Charlie!E37,'Mario S'!E37,David!E37) -> 3 | F19: =SUM(Allen!F37,Mike!F37,Jonah!F37,Jarren!F37,Chance!F37,'Jonathan Mach'!F37,Zach!F37,Hayden!F37,Kyle!F37,'Jonathan Mather'!F37,Cameron!F37,Emmet!F37,Jackson!F37,Khai!F37,'Mario Q'!F37,Aaron!F37,Ian!F37,Charlie!F37,'Mario S'!F37,David!F37) -> 3 | G19: =SUM(Allen!G37,Mike!G37,Jonah!G37,Jarren!G37,Chance!G37,'Jonathan Mach'!G37,Zach!G37,Hayden!G37,Kyle!G37,'Jonathan Mather'!G37,Cameron!G37,Emmet!G37,Jackson!G37,Khai!G37,'Mario Q'!G37,Aaron!G37,Ian!G37,Charlie!G37,'Mario S'!G37,David!G37) -> 5 | H19: =SUM(Allen!H37,Mike!H37,Jonah!H37,Jarren!H37,Chance!H37,'Jonathan Mach'!H37,Zach!H37,Hayden!H37,Kyle!H37,'Jonathan Mather'!H37,Cameron!H37,Emmet!H37,Jackson!H37,Khai!H37,'Mario Q'!H37,Aaron!H37,Ian!H37,Charlie!H37,'Mario S'!H37,David!H37) -> 4 | I19: =SUM(Allen!I37,Mike!I37,Jonah!I37,Jarren!I37,Chance!I37,'Jonathan Mach'!I37,Zach!I37,Hayden!I37,Kyle!I37,'Jonathan Mather'!I37,Cameron!I37,Emmet!I37,Jackson!I37,Khai!I37,'Mario Q'!I37,Aaron!I37,Ian!I37,Charlie!I37,'Mario S'!I37,David!I37) -> 4 | ... Y19: =SUM(Allen!Y37,Mike!Y37,Jonah!Y37,Jarren!Y37,Chance!Y37,'Jonathan Mach'!Y37,Zach!Y37,Hayden!Y37,Kyle!Y37,'Jonathan Mather'!Y37,Cameron!Y37,Emmet!Y37,Jackson!Y37,Khai!Y37,'Mario Q'!Y37,Aaron!Y37,Ian!Y37,Charlie!Y37,'Mario S'!Y37,David!Y37) -> 0
A20: Wednesday | B20: =SUM(Allen!B38,Mike!B38,Jonah!B38,Jarren!B38,Chance!B38,'Jonathan Mach'!B38,Zach!B38,Hayden!B38,Kyle!B38,'Jonathan Mather'!B38,Cameron!B38,Emmet!B38,Jackson!B38,Khai!B38,'Mario Q'!B38,Aaron!B38,Ian!B38,Charlie!B38,'Mario S'!B38,David!B38) -> 3 | C20: =SUM(Allen!C38,Mike!C38,Jonah!C38,Jarren!C38,Chance!C38,'Jonathan Mach'!C38,Zach!C38,Hayden!C38,Kyle!C38,'Jonathan Mather'!C38,Cameron!C38,Emmet!C38,Jackson!C38,Khai!C38,'Mario Q'!C38,Aaron!C38,Ian!C38,Charlie!C38,'Mario S'!C38,David!C38) -> 3 | D20: =SUM(Allen!D38,Mike!D38,Jonah!D38,Jarren!D38,Chance!D38,'Jonathan Mach'!D38,Zach!D38,Hayden!D38,Kyle!D38,'Jonathan Mather'!D38,Cameron!D38,Emmet!D38,Jackson!D38,Khai!D38,'Mario Q'!D38,Aaron!D38,Ian!D38,Charlie!D38,'Mario S'!D38,David!D38) -> 4 | E20: =SUM(Allen!E38,Mike!E38,Jonah!E38,Jarren!E38,Chance!E38,'Jonathan Mach'!E38,Zach!E38,Hayden!E38,Kyle!E38,'Jonathan Mather'!E38,Cameron!E38,Emmet!E38,Jackson!E38,Khai!E38,'Mario Q'!E38,Aaron!E38,Ian!E38,Charlie!E38,'Mario S'!E38,David!E38) -> 4 | F20: =SUM(Allen!F38,Mike!F38,Jonah!F38,Jarren!F38,Chance!F38,'Jonathan Mach'!F38,Zach!F38,Hayden!F38,Kyle!F38,'Jonathan Mather'!F38,Cameron!F38,Emmet!F38,Jackson!F38,Khai!F38,'Mario Q'!F38,Aaron!F38,Ian!F38,Charlie!F38,'Mario S'!F38,David!F38) -> 5 | G20: =SUM(Allen!G38,Mike!G38,Jonah!G38,Jarren!G38,Chance!G38,'Jonathan Mach'!G38,Zach!G38,Hayden!G38,Kyle!G38,'Jonathan Mather'!G38,Cameron!G38,Emmet!G38,Jackson!G38,Khai!G38,'Mario Q'!G38,Aaron!G38,Ian!G38,Charlie!G38,'Mario S'!G38,David!G38) -> 5 | H20: =SUM(Allen!H38,Mike!H38,Jonah!H38,Jarren!H38,Chance!H38,'Jonathan Mach'!H38,Zach!H38,Hayden!H38,Kyle!H38,'Jonathan Mather'!H38,Cameron!H38,Emmet!H38,Jackson!H38,Khai!H38,'Mario Q'!H38,Aaron!H38,Ian!H38,Charlie!H38,'Mario S'!H38,David!H38) -> 2 | I20: =SUM(Allen!I38,Mike!I38,Jonah!I38,Jarren!I38,Chance!I38,'Jonathan Mach'!I38,Zach!I38,Hayden!I38,Kyle!I38,'Jonathan Mather'!I38,Cameron!I38,Emmet!I38,Jackson!I38,Khai!I38,'Mario Q'!I38,Aaron!I38,Ian!I38,Charlie!I38,'Mario S'!I38,David!I38) -> 2 | ... U20: =SUM(Allen!U38,Mike!U38,Jonah!U38,Jarren!U38,Chance!U38,'Jonathan Mach'!U38,Zach!U38,Hayden!U38,Kyle!U38,'Jonathan Mather'!U38,Cameron!U38,Emmet!U38,Jackson!U38,Khai!U38,'Mario Q'!U38,Aaron!U38,Ian!U38,Charlie!U38,'Mario S'!U38,David!U38) -> 3
